const num = 4;
try {
    aalert(2)
} catch(err) {
    console.log(err)
}